Workbook

Sheet P&L AUTOMOBILES
D3: HERO MOTORS
L4: MARUTI SUZUKI
B5: Year | C5: 44256 | D5: 44621 | E5: 44986 | F5: 45352 | G5: 45717 | K5: 44256 | L5: 44621 | M5: 44986 | N5: 45352 | O5: 45717
B6: Sales - | C6: 30801 | D6: 29245 | E6: 33806 | F6: 37456 | G6: 40756 | J6: Sales - | K6: 70332 | L6: 88296 | M6: 117523 | N6: 140933 | O6: 151900
B7: Sales Growth % | C7: 0.0681 | D7: -0.0505 | E7: 0.1559 | F7: 0.108 | G7: 0.0881 | J7: Sales Growth % | K7: -0.0698 | L7: 0.2554 | M7: 0.331 | N7: 0.1992 | O7: 0.0778
B8: Expenses - | C8: 26777 | D8: 25866 | E8: 29815 | F8: 32194 | G8: 34885 | J8: Expenses - | K8: 64928 | L8: 82549 | M8: 106504 | N8: 124483 | O8: 134074
B9: Material Cost % + | C9: 0.71 | D9: 0.71 | E9: 0.71 | F9: 0.68 | G9: 0.66 | J9: Material Cost % - | K9: 0.72 | L9: 0.75 | M9: 0.73 | N9: 0.71 | O9: 0.71
B10: Manufacturing Cost % | C10: 0.01 | D10: 0.01 | E10: 0.01 | F10: 0.01 | G10: 0.01 | J10: Raw material cost | K10: 50544 | L10: 66129 | M10: 86647 | N10: 101050 | O10: 109361
B11: Employee Cost % | C11: 0.06 | D11: 0.07 | E11: 0.06 | F11: 0.07 | G11: 0.06 | J11: Change in inventory | K11: 273 | L11: -92 | M11: -404 | N11: -443 | O11: -890
B12: Other Cost % | C12: 0.09 | D12: 0.09 | E12: 0.1 | F12: 0.1 | G12: 0.12 | J12: Manufacturing Cost % | K12: 0.02 | L12: 0.02 | M12: 0.02 | N12: 0.01 | O12: 0.01
B13: Operating Profit | C13: 4024 | D13: 3379 | E13: 3991 | F13: 5261 | G13: 5872 | J13: Employee Cost % | K13: 0.05 | L13: 0.05 | M13: 0.04 | N13: 0.04 | O13: 0.04
B14: OPM % | C14: 0.13 | D14: 0.12 | E14: 0.12 | F14: 0.14 | G14: 0.14 | J14: Other Cost % | K14: 0.14 | L14: 0.12 | M14: 0.12 | N14: 0.12 | O14: 0.11
B15: Other Income - | C15: 575 | D15: 547 | E15: 560 | F15: 727 | G15: 1052 | J15: Operating Profit | K15: 5404 | L15: 5747 | M15: 11019 | N15: 16449 | O15: 17826
B16: Exceptional items | C16: 163 | D16: 92 | E16: 113 | F16: -39 | G16: 156 | J16: OPM % | K16: 0.08 | L16: 0.07 | M16: 0.09 | N16: 0.12 | O16: 0.12
B17: Other income normal | C17: 412 | D17: 455 | E17: 448 | F17: 766 | G17: 896 | J17: Other Income - | K17: 2887 | L17: 1748 | M17: 2150 | N17: 3807 | O17: 4710
... B28: Dividend Payout % | C28: 0.71 | D28: 0.77 | E28: 0.69 | F28: 0.71 | G28: 0.72 | J28: Profit for EPS | K28: 4230 | L28: 3766 | M28: 8049 | N28: 13209 | O28: 13955
J29: EPS in Rs | K29: 140.02 | L29: 124.68 | M29: 266.46 | N29: 420.14 | O29: 443.86
J30: Dividend Payout % | K30: 0.32 | L30: 0.48 | M30: 0.34 | N30: 0.3 | O30: 0.3
D36: Mahindra & Mahindra | M36: TVS MOTORS
C38: 44256 | D38: 44621 | E38: 44986 | F38: 45352 | G38: 45717 | K38: 44256 | L38: 44621 | M38: 44986 | N38: 45352 | O38: 45717
B39: Sales - | C39: 74278 | D39: 90171 | E39: 121269 | F39: 139078 | G39: 159211 | J39: Sales + | K39: 19421 | L39: 24355 | M39: 31974 | N39: 38779 | O39: 44089
B40: Sales Growth % | C40: -0.0146 | D40: 0.214 | E40: 0.3449 | F40: 0.1469 | G40: 0.1448 | J40: Expenses - | K40: 17189 | L40: 21601 | M40: 27947 | N40: 33344 | O40: 37514
B41: Expenses - | C41: 62791 | D41: 75488 | E41: 100983 | F41: 114186 | G41: 128693 | J41: Material Cost % - | K41: 0.67 | L41: 0.67 | M41: 0.65 | N41: 0.63 | O41: 0.61
B42: Material Cost % - | C42: 0.52 | D42: 0.57 | E42: 0.61 | F42: 0.6 | G42: 0.6 | J42: Raw material cost | K42: 12926 | L42: 16518 | M42: 20987 | N42: 24594 | O42: 26803
B43: Raw material cost | C43: 38271 | D43: 52665 | E43: 76020 | F43: 85070 | G43: 95755 | J43: Change in inventory | K43: 0 | L43: -260 | M43: -141 | N43: -323 | O43: -79
B44: Change in inventory | C44: 136 | D44: -862 | E44: -2032 | F44: -1455 | G44: -12 | J44: Manufacturing Cost % | K44: 0.01 | L44: 0.01 | M44: 0.01 | N44: 0.01 | O44: 0.01
B45: Manufacturing Cost % | C45: 0.04 | D45: 0.04 | E45: 0.04 | F45: 0.03 | G45: 0.03 | J45: Employee Cost % | K45: 0.09 | L45: 0.09 | M45: 0.09 | N45: 0.08 | O45: 0.08
B46: Employee Cost % | C46: 0.11 | D46: 0.09 | E46: 0.08 | F46: 0.08 | G46: 0.07 | J46: Other Cost % | K46: 0.12 | L46: 0.12 | M46: 0.12 | N46: 0.14 | O46: 0.15
B47: Other Cost % | C47: 0.18 | D47: 0.13 | E47: 0.1 | F47: 0.11 | G47: 0.11 | J47: Operating Profit | K47: 2232 | L47: 2755 | M47: 4027 | N47: 5435 | O47: 6575
B48: Operating Profit | C48: 11487 | D48: 14683 | E48: 20285 | F48: 24892 | G48: 30518 | J48: OPM % | K48: 0.11 | L48: 0.11 | M48: 0.13 | N48: 0.14 | O48: 0.15
B49: OPM % | C49: 0.15 | D49: 0.16 | E49: 0.17 | F49: 0.18 | G49: 0.19 | J49: Other Income - | K49: 36 | L49: -5 | M49: 136 | N49: 131 | O49: 99
B50: Other Income - | C50: 1152 | D50: 3204 | E50: 3961 | F50: 3298 | G50: 3718 | J50: Exceptional items | K50: -11 | L50: -37 | M50: 46 | N50: 118 | O50: 135
... B64: EPS in Rs | C64: 14.58 | D64: 52.91 | E64: 82.68 | F64: 90.62 | G64: 103.97 | J64: Dividend Payout % | K64: 0.28 | L64: 0.24 | M64: 0.18 | N64: 0.23 | O64: 0.21
B65: Dividend Payout % | C65: 0.54 | D65: 0.2 | E65: 0.18 | F65: 0.21 | G65: 0.22

Sheet BALANCE SHEET AUTOMOBILES
D3: HERO MOTORS
M4: MARUTI SUZUKI
B5: Year | C5: 44256 | D5: 44621 | E5: 44986 | F5: 45352 | G5: 45717 | K5: 44256 | L5: 44621 | M5: 44986 | N5: 45352 | O5: 45717
J6: Equity Capital | K6: 151 | L6: 151 | M6: 151 | N6: 157 | O6: 157
B7: Equity Capital | C7: 40 | D7: 40 | E7: 40 | F7: 40 | G7: 40 | J7: Reserves | K7: 51216 | L7: 53935 | M7: 60231 | N7: 83825 | O7: 93890
B8: Reserves | C8: 15158 | D8: 15743 | E8: 16665 | F8: 17946 | G8: 19767 | J8: Borrowings - | K8: 531 | L8: 419 | M8: 1247 | N8: 119 | O8: 76
B9: Borrowings - | C9: 150 | D9: 168 | E9: 156 | F9: 138 | G9: 163 | J9: Long term Borrowings | K9: 0 | L9: 0 | M9: 0 | N9: 0 | O9: 0
B10: Lease Liabilities | C10: 150 | D10: 168 | E10: 156 | F10: 138 | G10: 163 | J10: Short term Borrowings | K10: 489 | L10: 382 | M10: 1216 | N10: 33 | O10: 0
B11: Other Borrowings | C11: 0 | D11: 0 | E11: 0 | F11: 0 | G11: 0 | J11: Lease Liabilities | K11: 42 | L11: 37 | M11: 32 | N11: 86 | O11: 76
B12: Other Liabilities - | C12: 6813 | D12: 5763 | E12: 6402 | F12: 7448 | G12: 7950 | J12: Other Borrowings | K12: 0 | L12: 0 | M12: 0 | N12: 0 | O12: 0
B13: Trade Payables | C13: 5205 | D13: 4260 | E13: 4704 | F13: 5528 | G13: 5566 | J13: Other Liabilities - | K13: 18263 | L13: 18889 | M13: 21549 | N13: 26184 | O13: 31497
B14: Advance from Customers | C14: 62 | D14: 112 | E14: 78 | F14: 73 | G14: 92 | J14: Trade Payables | K14: 10162 | L14: 9761 | M14: 11780 | N14: 14582 | O14: 17421
B15: Other liability items | C15: 1546 | D15: 1390 | E15: 1619 | F15: 1847 | G15: 2292 | J15: Advance from Customers | K15: 1018 | L15: 1125 | M15: 1456 | N15: 1460 | O15: 1130
B16: Total Liabilities | C16: 22161 | D16: 21714 | E16: 23263 | F16: 25572 | G16: 27920 | J16: Other liability items | K16: 7084 | L16: 8004 | M16: 8313 | N16: 10142 | O16: 12946
B17: Fixed Assets - | C17: 5988 | D17: 5806 | E17: 5761 | F17: 5834 | G17: 5901 | J17: Total Liabilities | K17: 70161 | L17: 73394 | M17: 83179 | N17: 110285 | O17: 125620
B18: Land | C18: 442 | D18: 431 | E18: 430 | F18: 430 | G18: 427 | J18: Fixed Assets - | K18: 14957 | L18: 13717 | M18: 17805 | N18: 18495 | O18: 24707
... B37: Total Assets | C37: 22161 | D37: 21714 | E37: 23263 | F37: 25572 | G37: 27920 | J37: Total Assets | K37: 70161 | L37: 73394 | M37: 83179 | N37: 110285 | O37: 125620
D44: Mahindra & Mahindra | K44: TVS MOTORS
C46: 44256 | D46: 44621 | E46: 44986 | F46: 45352 | G46: 45717 | K46: 44256 | L46: 44621 | M46: 44986 | N46: 45352 | O46: 45717
B47: Equity Capital | C47: 555 | D47: 556 | E47: 557 | F47: 557 | G47: 558 | J47: Equity Capital | K47: 48 | L47: 48 | M47: 48 | N47: 48 | O47: 48
B48: Reserves | C48: 41027 | D48: 46567 | E48: 55809 | F48: 65633 | G48: 76481 | J48: Reserves | K48: 3779 | L48: 4352 | M48: 5457 | N48: 6736 | O48: 8456
B49: Borrowings - | C49: 80625 | D49: 77605 | E49: 92247 | F49: 108647 | G49: 129025 | J49: Borrowings - | K49: 12179 | L49: 15827 | M49: 22376 | N49: 26006 | O49: 28609
B50: Long term Borrowings | C50: 52778 | D50: 48625 | E50: 55027 | F50: 69741 | G50: 83782 | J50: Long term Borrowings | K50: 6280 | L50: 7306 | M50: 9064 | N50: 12629 | O50: 13933
B51: Short term Borrowings | C51: 4647 | D51: 26042 | E51: 33740 | F51: 35484 | G51: 41466 | J51: Short term Borrowings | K51: 3069 | L51: 7992 | M51: 12562 | N51: 12657 | O51: 13683
B52: Lease Liabilities | C52: 2666 | D52: 2938 | E52: 3480 | F52: 3422 | G52: 3776 | J52: Lease Liabilities | K52: 248 | L52: 530 | M52: 749 | N52: 719 | O52: 993
B53: Preference Capital | C53: 0 | D53: 0 | E53: 0 | F53: 2022 | G53: 4075 | J53: Other Borrowings | K53: 2581 | L53: 0 | M53: 0 | N53: 0 | O53: 0
B54: Other Borrowings | C54: 20533 | D54: 0 | E54: 0 | F54: -2022 | G54: -4075 | J54: Other Liabilities - | K54: 5859 | L54: 6692 | M54: 7144 | N54: 9235 | O54: 10539
B55: Other Liabilities - | C55: 42762 | D55: 47661 | E55: 55670 | F55: 59884 | G55: 69950 | J55: Non controlling int | K55: 388 | L55: 654 | M55: 405 | N55: 728 | O55: 939
B56: Non controlling int | C56: 9070 | D56: 9703 | E56: 10716 | F56: 11319 | G56: 12059 | J56: Trade Payables | K56: 4299 | L56: 4663 | M56: 5097 | N56: 6638 | O56: 7561
B57: Trade Payables | C57: 15506 | D57: 19037 | E57: 23836 | F57: 25666 | G57: 30855 | J57: Advance from Customers | K57: 176 | L57: 278 | M57: 338 | N57: 258 | O57: 394
B58: Advance from Customers | C58: 0 | D58: 0 | E58: 0 | F58: 0 | G58: 0 | J58: Other liability items | K58: 997 | L58: 1098 | M58: 1304 | N58: 1611 | O58: 1645
... B82: Other asset items | C82: 49383 | D82: 51277 | E82: 68061 | F82: 86222 | G82: 97900 | J82: Total Assets | K82: 21865 | L82: 26919 | M82: 35025 | N82: 42024 | O82: 47651
B83: Total Assets | C83: 164968 | D83: 172388 | E83: 204283 | F83: 234722 | G83: 276013

Sheet P&L IT
D2: INFOSYS | M2: TCS
C3: 44256 | D3: 44621 | E3: 44986 | F3: 45352 | G3: 45717 | L3: 44256 | M3: 44621 | N3: 44986 | O3: 45352 | P3: 45717
B4: Sales - | C4: 100472 | D4: 121641 | E4: 146767 | F4: 153670 | G4: 162990 | K4: Sales - | L4: 164177 | M4: 191754 | N4: 225458 | O4: 240893 | P4: 255324
B5: Sales Growth % | C5: 0.1066 | D5: 0.2107 | E5: 0.2066 | F5: 0.047 | G5: 0.0606 | K5: Sales Growth % | L5: 0.0461 | M5: 0.168 | N5: 0.1758 | O5: 0.0685 | P5: 0.0599
B6: Expenses - | C6: 72583 | D6: 90150 | E6: 111637 | F6: 117245 | G6: 123754 | K6: Expenses - | L6: 117631 | M6: 138697 | N6: 166199 | O6: 176597 | P6: 187917
B7: Manufacturing Cost % | C7: 0.13 | D7: 0.17 | E7: 0.18 | F7: 0.18 | G7: 0.19 | K7: Material Cost % + | L7: 0 | M7: 0 | N7: 0 | O7: 0 | P7: 0
B8: Employee Cost % | C8: 0.55 | D8: 0.53 | E8: 0.53 | F8: 0.54 | G8: 0.53 | K8: Manufacturing Cost % | L8: 0.01 | M8: 0.01 | N8: 0.01 | O8: 0.02 | P8: 0.05
B9: Other Cost % | C9: 0.04 | D9: 0.04 | E9: 0.05 | F9: 0.05 | G9: 0.04 | K9: Employee Cost % | L9: 0.56 | M9: 0.56 | N9: 0.57 | O9: 0.58 | P9: 0.57
B10: Operating Profit | C10: 27889 | D10: 31491 | E10: 35130 | F10: 36425 | G10: 39236 | K10: Other Cost % | L10: 0.15 | M10: 0.16 | N10: 0.16 | O10: 0.14 | P10: 0.12
B11: OPM % | C11: 0.28 | D11: 0.26 | E11: 0.24 | F11: 0.24 | G11: 0.24 | K11: Operating Profit | L11: 46546 | M11: 53057 | N11: 59259 | O11: 64296 | P11: 67407
B12: Other Income - | C12: 2201 | D12: 2295 | E12: 2701 | F12: 4711 | G12: 3600 | K12: OPM % | L12: 0.28 | M12: 0.28 | N12: 0.26 | O12: 0.27 | P12: 0.26
B13: Exceptional items | C13: 74 | D13: 177 | E13: 148 | F13: 285 | G13: 291 | K13: Other Income - | L13: 1916 | M13: 4018 | N13: 3449 | O13: 3464 | P13: 3962
B14: Other income normal | C14: 2127 | D14: 2118 | E14: 2553 | F14: 4426 | G14: 3309 | K14: Exceptional items | L14: -1205 | M14: 23 | N14: 30 | O14: -933 | P14: 46
B15: Interest | C15: 195 | D15: 200 | E15: 284 | F15: 470 | G15: 416 | K15: Other income normal | L15: 3121 | M15: 3995 | N15: 3419 | O15: 4397 | P15: 3916
... B27: Dividend Payout % | C27: 0.59 | D27: 0.59 | E27: 0.58 | F27: 0.73 | G27: 0.67 | K27: Dividend Payout % | L27: 0.43 | M27: 0.41 | N27: 1 | O27: 0.58 | P27: 0.94
N31: HCL
D32: WIPRO | L32: 44256 | M32: 44621 | N32: 44986 | O32: 45352 | P32: 45717
C33: 44256 | D33: 44621 | E33: 44986 | F33: 45352 | G33: 45717 | K33: Sales - | L33: 75379 | M33: 85651 | N33: 101456 | O33: 109913 | P33: 117055
B34: Sales - | C34: 61935 | D34: 79312 | E34: 90488 | F34: 89760 | G34: 89088 | K34: Sales Growth % | L34: 0.0665 | M34: 0.1363 | N34: 0.1845 | O34: 0.0834 | P34: 0.065
B35: Sales Growth % | C35: 0.013 | D35: 0.2806 | E35: 0.1409 | F35: -0.008 | G35: -0.0075 | K35: Expenses - | L35: 55331 | M35: 65122 | N35: 78828 | O35: 85715 | P35: 91551
B36: Expenses - | C36: 47164 | D36: 62628 | E36: 73649 | F36: 73008 | G36: 71067 | K36: Material Cost % - | L36: 0.02 | M36: 0.02 | N36: 0.02 | O36: 0.02 | P36: 0.02
B37: Material Cost % + | C37: 0.01 | D37: 0.01 | E37: 0.01 | F37: 0 | G37: 0 | K37: Raw material cost | L37: 1698 | M37: 1473 | N37: 2072 | O37: 1754 | P37: 1976
B38: Manufacturing Cost % | C38: 0 | D38: 0.15 | E38: 0.15 | F38: 0.84 | G38: 0.83 | K38: Change in inventory | L38: -3 | M38: -67 | N38: -67 | O38: 43 | P38: 52
B39: Employee Cost % | C39: 0.54 | D39: 0.57 | E39: 0.59 | F39: 0.61 | G39: 0.6 | K39: Manufacturing Cost % | L39: 0.16 | M39: 0.17 | N39: 0.17 | O39: 0.15 | P39: 0.14
B40: Other Cost % | C40: 0.21 | D40: 0.06 | E40: 0.06 | F40: -0.64 | G40: -0.63 | K40: Employee Cost % | L40: 0.52 | M40: 0.54 | N40: 0.54 | O40: 0.57 | P40: 0.57
B41: Operating Profit | C41: 14771 | D41: 16684 | E41: 16839 | F41: 16752 | G41: 18021 | K41: Other Cost % | L41: 0.03 | M41: 0.03 | N41: 0.04 | O41: 0.04 | P41: 0.05
B42: OPM % | C42: 0.24 | D42: 0.21 | E42: 0.19 | F42: 0.19 | G42: 0.2 | K42: Operating Profit | L42: 20048 | M42: 20529 | N42: 22628 | O42: 24198 | P42: 25504
B43: Other Income - | C43: 2404 | D43: 2067 | E43: 2275 | F43: 2631 | G43: 3909 | K43: OPM % | L43: 0.27 | M43: 0.24 | N43: 0.22 | O43: 0.22 | P43: 0.22
B44: Exceptional items | C44: 0 | D44: 0 | E44: 9 | F44: 207 | G44: 61 | K44: Other Income - | L44: 927 | M44: 1067 | N44: 1358 | O44: 1495 | P44: 2485
B45: Other income normal | C45: 2404 | D45: 2067 | E45: 2266 | F45: 2424 | G45: 3849 | K45: Exceptional items | L45: 215 | M45: 118 | N45: 265 | O45: 172 | P45: 202
... B57: Dividend Payout % | C57: 0.05 | D57: 0.27 | E57: 0.05 | F57: 0.05 | G57: 0.48 | K57: Profit for EPS | L57: 11145 | M57: 13499 | N57: 14851 | O57: 15702 | P57: 17390
K58: EPS in Rs | L58: 41.07 | M58: 49.74 | N58: 54.73 | O58: 57.86 | P58: 64.08
K59: Dividend Payout % | L59: 0.24 | M59: 0.84 | N59: 0.88 | O59: 0.9 | P59: 0.94

Sheet BALANCE SHEET IT
D2: INFOSYS | N2: TCS
C3: 44256 | D3: 44621 | E3: 44986 | F3: 45352 | G3: 45717 | L3: 44256 | M3: 44621 | N3: 44986 | O3: 45352 | P3: 45717
B4: Equity Capital | C4: 2124 | D4: 2098 | E4: 2069 | F4: 2071 | G4: 2073 | K4: Equity Capital | L4: 370 | M4: 366 | N4: 366 | O4: 362 | P4: 362
B5: Reserves | C5: 74227 | D5: 73252 | E5: 73338 | F5: 86045 | G5: 93745 | K5: Reserves | L5: 86063 | M5: 88773 | N5: 90058 | O5: 90127 | P5: 94394
B6: Borrowings - | C6: 5325 | D6: 5474 | E6: 8299 | F6: 8359 | G6: 8227 | K6: Borrowings - | L6: 7795 | M6: 7818 | N6: 7688 | O6: 8021 | P6: 9392
B7: Lease Liabilities | C7: 5325 | D7: 5474 | E7: 8299 | F7: 8359 | G7: 8227 | K7: Long term Borrowings | L7: 0 | M7: 0 | N7: 0 | O7: 0 | P7: 0
B8: Other Liabilities - | C8: 25835 | D8: 35905 | E8: 40890 | F8: 40885 | G8: 43750 | K8: Short term Borrowings | L8: 0 | M8: 0 | N8: 0 | O8: 0 | P8: 0
B9: Non controlling int | C9: 431 | D9: 386 | E9: 388 | F9: 345 | G9: 385 | K9: Lease Liabilities | L9: 7795 | M9: 7818 | N9: 7688 | O9: 8021 | P9: 9392
B10: Trade Payables | C10: 2645 | D10: 4134 | E10: 3865 | F10: 3956 | G10: 4164 | K10: Other Borrowings | L10: 0 | M10: 0 | N10: 0 | O10: 0 | P10: 0
B11: Advance from Customers | C11: 0 | D11: 0 | E11: 0 | F11: 0 | G11: 0 | K11: Other Liabilities - | L11: 35764 | M11: 43967 | N11: 44747 | O11: 46962 | P11: 54501
B12: Other liability items | C12: 22759 | D12: 31385 | E12: 36637 | F12: 36584 | G12: 39201 | K12: Non controlling int | L12: 675 | M12: 707 | N12: 782 | O12: 830 | P12: 1015
B13: Total Liabilities | C13: 107511 | D13: 116729 | E13: 124596 | F13: 137360 | G13: 147795 | K13: Trade Payables | L13: 7860 | M13: 8045 | N13: 10515 | O13: 9981 | P13: 13909
B14: Fixed Assets - | C14: 25505 | D14: 25800 | E14: 29225 | F14: 27622 | G14: 30961 | K14: Advance from Customers | L14: 312 | M14: 468 | N14: 543 | O14: 1841 | P14: 1896
B15: Land | C15: 2036 | D15: 2065 | E15: 2054 | F15: 2037 | G15: 2079 | K15: Other liability items | L15: 26917 | M15: 34747 | N15: 32907 | O15: 34310 | P15: 37681
... B33: Total Assets | C33: 107511 | D33: 116729 | E33: 124596 | F33: 137360 | G33: 147795 | K33: Trade receivables + | L33: 30079 | M33: 41810 | N33: 49954 | O33: 53577 | P33: 59046
K34: Cash Equivalents | L34: 9329 | M34: 18221 | N34: 11032 | O34: 13286 | P34: 15463
K35: Loans n Advances | L35: 5107 | M35: 3600 | N35: 2097 | O35: 3989 | P35: 4612
K36: Other asset items | L36: 34149 | M36: 24285 | N36: 20836 | O36: 21662 | P36: 23944
K37: Total Assets | L37: 129992 | M37: 140924 | N37: 142859 | O37: 145472 | P37: 158649
D41: WIPRO | N41: HCL
C42: 44256 | D42: 44621 | E42: 44986 | F42: 45352 | G42: 45717 | L42: 44256 | M42: 44621 | N42: 44986 | O42: 45352 | P42: 45717
B43: Equity Capital | C43: 1096 | D43: 1096 | E43: 1098 | F43: 1045 | G43: 2094 | K43: Equity Capital | L43: 543 | M43: 543 | N43: 543 | O43: 543 | P43: 543
B44: Reserves | C44: 53805 | D44: 64307 | E44: 76570 | F44: 73943 | G44: 80736 | K44: Reserves | L44: 59370 | M44: 61371 | N44: 64862 | O44: 67720 | P44: 69112
B45: Borrowings - | C45: 10451 | D45: 17593 | E45: 17467 | F45: 16465 | G45: 19204 | K45: Borrowings - | L45: 6864 | M45: 6343 | N45: 4794 | O45: 5758 | P45: 6276
B46: Long term Borrowings | C46: 746 | D46: 5646 | E46: 6127 | F46: 6230 | G46: 6395 | K46: Long term Borrowings | L46: 3828 | M46: 3923 | N46: 2111 | O46: 2223 | P46: 70
B47: Short term Borrowings | C47: 6036 | D47: 9523 | E47: 8882 | F47: 7917 | G47: 9786 | K47: Short term Borrowings | L47: 79 | M47: 62 | N47: 140 | O47: 104 | P47: 2221
B48: Lease Liabilities | C48: 2118 | D48: 2423 | E48: 2457 | F48: 2318 | G48: 3022 | K48: Lease Liabilities | L48: 2594 | M48: 2358 | N48: 2535 | O48: 3429 | P48: 3985
B49: Other Borrowings | C49: 1551 | D49: 0 | E49: 0 | F49: 0 | G49: 0 | K49: Other Borrowings | L49: 363 | M49: 0 | N49: 8 | O49: 2 | P49: 0
B50: Other Liabilities - | C50: 17213 | D50: 24280 | E50: 21789 | F50: 23611 | G50: 26362 | K50: Other Liabilities - | L50: 19270 | M50: 20664 | N50: 23051 | O50: 24985 | P50: 28549
B51: Non controlling int | C51: 150 | D51: 52 | E51: 59 | F51: 134 | G51: 214 | K51: Non controlling int | L51: 169 | M51: 92 | N51: -7 | O51: 8 | P51: 18
B52: Trade Payables | C52: 5417 | D52: 6252 | E52: 5972 | F52: 8857 | G52: 8825 | K52: Trade Payables | L52: 5457 | M52: 6278 | N52: 6428 | O52: 5853 | P52: 6225
B53: Advance from Customers | C53: 36 | D53: 63 | E53: 64 | F53: 119 | G53: 79 | K53: Advance from Customers | L53: 320 | M53: 222 | N53: 252 | O53: 158 | P53: 204
B54: Other liability items | C54: 11610 | D54: 17913 | E54: 15694 | F54: 14501 | G54: 17244 | K54: Other liability items | L54: 13324 | M54: 14072 | N54: 16378 | O54: 18966 | P54: 22102
... B76: Total Assets | C76: 82566 | D76: 107276 | E76: 116924 | F76: 115064 | G76: 128396 | K76: Total Assets | L76: 86047 | M76: 88921 | N76: 93250 | O76: 99006 | P76: 104480

Sheet CASH FLOW AUTOMOBILES
C4: HERO MOTORS
M5: MARUTI SUZUKI
B6: Year | C6: 44256 | D6: 44621 | E6: 44986 | F6: 45352 | G6: 45717 | K6: 44256 | L6: 44621 | M6: 44986 | N6: 45352 | O6: 45717
B7: Cash from Operating Activity - | C7: 4173 | D7: 2020 | E7: 2579 | F7: 4907 | G7: 4182 | J7: Cash from Operating Activity - | K7: 8839 | L7: 1791 | M7: 9228 | N7: 15167 | O7: 14012
B8: Profit from operations | C8: 4079 | D8: 3472 | E8: 4012 | F8: 5146 | G8: 6050 | J8: Profit from operations | K8: 5514 | L8: 5778 | M8: 11081 | N8: 16445 | O8: 17899
B9: Receivables | C9: -869 | D9: 122 | E9: -499 | F9: 77 | G9: -977 | J9: Receivables | K9: 697 | L9: -763 | M9: -1257 | N9: -1310 | O9: -1963
B10: Inventory | C10: -378 | D10: 347 | E10: -311 | F10: -10 | G10: -14 | J10: Inventory | K10: 165 | L10: -483 | M10: -751 | N10: 164 | O10: -1003
B11: Payables | C11: 2174 | D11: -944 | E11: 444 | F11: 824 | G11: 38 | J11: Payables | K11: 2678 | L11: -394 | M11: 2007 | N11: 2811 | O11: 2835
B12: Loans Advances | C12: -9 | D12: -1 | E12: -3 | F12: -2 | G12: -6 | J12: Loans Advances | K12: -6 | L12: -8 | M12: 1 | N12: -3 | O12: -10
B13: Other WC items | C13: 152 | D13: -207 | E13: -214 | F13: 186 | G13: 626 | J13: Other WC items | K13: 801 | L13: -1163 | M13: 379 | N13: 615 | O13: 36
B14: Working capital changes | C14: 1070 | D14: -682 | E14: -583 | F14: 1075 | G14: -334 | J14: Working capital changes | K14: 4335 | L14: -2810 | M14: 379 | N14: 2278 | O14: -105
B15: Direct taxes | C15: -976 | D15: -769 | E15: -850 | F15: -1314 | G15: -1534 | J15: Direct taxes | K15: -1011 | L15: -1177 | M15: -2231 | N15: -3556 | O15: -3782
B16: Cash from Investing Activity - | C16: -2210 | D16: -152 | E16: -469 | F16: -1802 | G16: -1586 | J16: Cash from Investing Activity - | K16: -7284 | L16: -189 | M16: -8018 | N16: -10683 | O16: -10242
B17: Fixed assets purchased | C17: -515 | D17: -535 | E17: -578 | F17: -720 | G17: -827 | J17: Fixed assets purchased | K17: -2370 | L17: -3459 | M17: -6346 | N17: -7008 | O17: -8733
B18: Fixed assets sold | C18: 4 | D18: 11 | E18: 10 | F18: 9 | G18: 17 | J18: Fixed assets sold | K18: 42 | L18: 136 | M18: 99 | N18: 44 | O18: 33
... B33: Net Cash Flow | C33: 21 | D33: -71 | E33: 70 | F33: 372 | G33: -251 | J33: Net Cash Flow | K33: 14 | L33: 0 | M33: 1 | N33: 422 | O33: -378
C37: Mahindra & Mahindra | M37: TVS MOTORS
C38: 44256 | D38: 44621 | E38: 44986 | F38: 45352 | G38: 45717 | K38: 44256 | L38: 44621 | M38: 44986 | N38: 45352 | O38: 45717
B39: Cash from Operating Activity - | C39: 17909 | D39: 9248 | E39: -7074 | F39: -5630 | G39: 3176 | J39: Cash from Operating Activity - | K39: 1151 | L39: -1575 | M39: -4405 | N39: -1253 | O39: 3503
B40: Profit from operations | C40: 7588 | D40: 10515 | E40: 15642 | F40: 17541 | G40: 22050 | J40: Profit from operations | K40: 1559 | L40: 1919 | M40: 2931 | N40: 3974 | O40: 4966
B41: Receivables | C41: 4896 | D41: -2506 | E41: -21702 | F41: -21777 | G41: -20952 | J41: Receivables | K41: 399 | L41: -143 | M41: -95 | N41: -590 | O41: 110
B42: Inventory | C42: 226 | D42: -2173 | E42: -5252 | F42: -1753 | G42: -1646 | J42: Inventory | K42: -179 | L42: -275 | M42: -314 | N42: -327 | O42: -168
B43: Payables | C43: 7049 | D43: 4972 | E43: 7013 | F43: 4354 | G43: 8485 | J43: Payables | K43: 1114 | L43: 366 | M43: 517 | N43: 1538 | O43: 924
B44: Loans Advances | C44: 0 | D44: 0 | E44: 0 | F44: 0 | G44: 0 | J44: Loans Advances | K44: -1701 | L44: -2860 | M44: -6531 | N44: -4925 | O44: -829
B45: Other WC items | C45: 0 | D45: 0 | E45: 0 | F45: 0 | G45: 0 | J45: Other WC items | K45: 210 | L45: -217 | M45: -305 | N45: 37 | O45: -354
B46: Working capital changes | C46: 12171 | D46: 293 | E46: -19941 | F46: -19175 | G46: -14113 | J46: Working capital changes | K46: -157 | L46: -3128 | M46: -6727 | N46: -4268 | O46: -316
B47: Direct taxes | C47: -1850 | D47: -1560 | E47: -2775 | F47: -3996 | G47: -4761 | J47: Direct taxes | K47: -251 | L47: -366 | M47: -608 | N47: -959 | O47: -1147
B48: Cash from Investing Activity - | C48: -19686 | D48: -3252 | E48: -8866 | F48: -5615 | G48: -18616 | J48: Cash from Investing Activity - | K48: -882 | L48: -1471 | M48: -1308 | N48: -1481 | O48: -2899
B49: Fixed assets purchased | C49: -5989 | D49: -6040 | E49: -6305 | F49: -9946 | G49: -10392 | J49: Fixed assets purchased | K49: -928 | L49: -970 | M49: -1341 | N49: -1145 | O49: -2478
B50: Fixed assets sold | C50: 1364 | D50: 120 | E50: 138 | F50: 273 | G50: 583 | J50: Fixed assets sold | K50: 3 | L50: 14 | M50: 22 | N50: 35 | O50: 19
... B68: Other financing items | C68: 1444 | D68: -240 | E68: 386 | F68: 1408 | G68: 2062 | J68: Net Cash Flow | K68: 532 | L68: -128 | M68: 406 | N68: 505 | O68: 1759
B69: Net Cash Flow | C69: -1370 | D69: 113 | E69: 6 | F69: 1037 | G69: 394

Sheet CASH FLOW IT 
D3: INFOSYS | L3: TCS
C4: 44256 | D4: 44621 | E4: 44986 | F4: 45352 | G4: 45717 | K4: 44256 | L4: 44621 | M4: 44986 | N4: 45352 | O4: 45717
B5: Cash from Operating Activity - | C5: 23224 | D5: 23885 | E5: 22467 | F5: 25210 | G5: 35694 | J5: Cash from Operating Activity - | K5: 38802 | L5: 39949 | M5: 41965 | N5: 44338 | O5: 48908
B6: Profit from operations | C6: 28845 | D6: 32921 | E6: 37605 | F6: 39523 | G6: 41591 | J6: Profit from operations | K6: 47031 | L6: 54204 | M6: 59148 | N6: 63709 | O6: 67853
B7: Receivables | C7: -1835 | D7: -7937 | E7: -7076 | F7: -2667 | G7: -1769 | J7: Receivables | K7: 1059 | L7: -5144 | M7: -7683 | N7: -3332 | O7: -5228
B8: Payables | C8: -245 | D8: 1489 | E8: -279 | F8: 91 | G8: 176 | J8: Inventory | K8: -3 | L8: -12 | M8: -8 | N8: 0 | O8: 7
B9: Loans Advances | C9: -534 | D9: -1914 | E9: -3108 | F9: -1172 | G9: -1024 | J9: Payables | K9: -93 | L9: 186 | M9: 2036 | N9: -632 | O9: 3718
B10: Other WC items | C10: 3382 | D10: 6938 | E10: 4119 | F10: -1334 | G10: 2322 | J10: Loans Advances | K10: -17 | L10: -116 | M10: 261 | N10: -301 | O10: -738
B11: Working capital changes | C11: 768 | D11: -1424 | E11: -6344 | F11: -5082 | G11: -295 | J11: Other WC items | K11: -83 | L11: 2317 | M11: 1177 | N11: -2617 | O11: -1118
B12: Direct taxes | C12: -6389 | D12: -7612 | E12: -8794 | F12: -9231 | G12: -5602 | J12: Working capital changes | K12: 863 | L12: -2769 | M12: -4217 | N12: -6882 | O12: -3359
B13: Cash from Investing Activity - | C13: -7373 | D13: -6485 | E13: -1071 | F13: -5093 | G13: -1864 | J13: Direct taxes | K13: -9092 | L13: -11486 | M13: -12966 | N13: -12489 | O13: -15586
B14: Fixed assets purchased | C14: -2107 | D14: -2161 | E14: -2579 | F14: -2201 | G14: -2237 | J14: Cash from Investing Activity - | K14: -7956 | L14: -738 | M14: 548 | N14: 6091 | O14: -2144
B15: Fixed assets sold | C15: 0 | D15: 0 | E15: 0 | F15: 0 | G15: 0 | J15: Fixed assets purchased | K15: -3176 | L15: -2995 | M15: -3100 | N15: -2674 | O15: -3937
B16: Investments purchased | C16: -46738 | D16: -59951 | E16: -75800 | F16: -78118 | G16: -82753 | J16: Fixed assets sold | K16: 37 | L16: 31 | M16: 37 | N16: 24 | O16: 23
... B29: Net Cash Flow | C29: 6065 | D29: -7242 | E29: -5299 | F29: 2613 | G29: 9669 | J29: Dividends paid | K29: -10907 | L29: -13375 | M29: -41410 | N29: -25218 | O29: -44962
J30: Financial liabilities | K30: -1336 | L30: -1417 | M30: -1515 | N30: -1614 | O30: -1664
J31: Other financing items | K31: -19757 | L31: -18091 | M31: -4192 | N31: -21430 | O31: 28
J32: Net Cash Flow | K32: -1788 | L32: 5630 | M32: -5365 | N32: 1893 | O32: -674
L36: HCL
D37: WIPRO | K37: 44256 | L37: 44621 | M37: 44986 | N37: 45352 | O37: 45717
C38: 44256 | D38: 44621 | E38: 44986 | F38: 45352 | G38: 45717 | J38: Cash from Operating Activity - | K38: 19618 | L38: 16900 | M38: 18009 | N38: 22448 | O38: 22261
B39: Cash from Operating Activity - | C39: 14755 | D39: 11080 | E39: 13060 | F39: 17622 | G39: 16943 | J39: Profit from operations | K39: 20022 | L39: 20892 | M39: 23012 | N39: 24355 | O39: 25494
B40: Profit from operations | C40: 14954 | D40: 17297 | E40: 17538 | F40: 17416 | G40: 18533 | J40: Receivables | K40: 585 | L40: -2809 | M40: -3240 | N40: 248 | O40: -119
B41: Receivables | C41: 1285 | D41: -4323 | E41: -98 | F41: 782 | G41: 189 | J41: Inventory | K41: 72 | L41: 207 | M41: -37 | N41: 60 | O41: 77
B42: Inventory | C42: 80 | D42: -26 | E42: 16 | F42: 29 | G42: 21 | J42: Payables | K42: 608 | L42: 718 | M42: -175 | N42: -681 | O42: 249
B43: Payables | C43: 570 | D43: 970 | E43: -982 | F43: -44 | G43: 55 | J43: Loans Advances | K43: 0 | L43: 0 | M43: 0 | N43: 0 | O43: 0
B44: Loans Advances | C44: 0 | D44: 0 | E44: 0 | F44: 0 | G44: 0 | J44: Other WC items | K44: 1776 | L44: 1335 | M44: 2147 | N44: 2678 | O44: 803
B45: Other WC items | C45: 357 | D45: -270 | E45: -391 | F45: 974 | G45: 762 | J45: Working capital changes | K45: 3041 | L45: -549 | M45: -1305 | N45: 2305 | O45: 1010
B46: Working capital changes | C46: 2292 | D46: -3649 | E46: -1456 | F46: 1741 | G46: 1027 | J46: Direct taxes | K46: -3445 | L46: -3443 | M46: -3698 | N46: -4212 | O46: -4243
B47: Direct taxes | C47: -2492 | D47: -2569 | E47: -3022 | F47: -1536 | G47: -2618 | J47: Cash from Investing Activity - | K47: -5665 | L47: 1597 | M47: -3573 | N47: -6608 | O47: -4896
B48: Cash from Investing Activity - | C48: 685 | D48: -22321 | E48: -8169 | F48: 1144 | G48: -8044 | J48: Fixed assets purchased | K48: -1904 | L48: -1645 | M48: -1661 | N48: -1048 | O48: -1108
B49: Fixed assets purchased | C49: -1958 | D49: -2015 | E49: -1483 | F49: -1051 | G49: -1474 | J49: Fixed assets sold | K49: 151 | L49: 90 | M49: 217 | N49: 32 | O49: 25
B50: Fixed assets sold | C50: 75 | D50: 74 | E50: 55 | F50: 402 | G50: 182 | J50: Capital WIP | K50: 0 | L50: 0 | M50: 0 | N50: 0 | O50: 0
... B68: Net Cash Flow | C68: 2556 | D68: -6583 | E68: -1197 | F68: 509 | G68: 2502 | J68: Other financing items | K68: -12 | L68: -1550 | M68: 0 | N68: 7 | O68: -676
J69: Net Cash Flow | K69: 2761 | L69: 3989 | M69: -1445 | N69: 376 | O69: -1196

Sheet RATIO
C2: HERO MOTORS | M2: INFOSYS
B3: Particulars | C3: 2021 | D3: 2022 | E3: 2023 | F3: 2024 | G3: 2025 | L3: Particulars | M3: 2021 | N3: 2022 | O3: 2023 | P3: 2024 | Q3: 2025
B4: Total Debt | C4: ='BALANCE SHEET AUTOMOBILES'!C9 -> 150 | D4: ='BALANCE SHEET AUTOMOBILES'!D9 -> 168 | E4: ='BALANCE SHEET AUTOMOBILES'!E9 -> 156 | F4: ='BALANCE SHEET AUTOMOBILES'!F9 -> 138 | G4: ='BALANCE SHEET AUTOMOBILES'!G9 -> 163 | L4: Total Debt | M4: ='BALANCE SHEET IT'!C6 -> 5325 | N4: ='BALANCE SHEET IT'!D6 -> 5474 | O4: ='BALANCE SHEET IT'!E6 -> 8299 | P4: ='BALANCE SHEET IT'!F6 -> 8359 | Q4: ='BALANCE SHEET IT'!G6 -> 8227
B5: Total Equity | C5: ='BALANCE SHEET AUTOMOBILES'!C7+'BALANCE SHEET AUTOMOBILES'!C8 -> 15198 | D5: ='BALANCE SHEET AUTOMOBILES'!D7+'BALANCE SHEET AUTOMOBILES'!D8 -> 15783 | E5: ='BALANCE SHEET AUTOMOBILES'!E7+'BALANCE SHEET AUTOMOBILES'!E8 -> 16705 | F5: ='BALANCE SHEET AUTOMOBILES'!F7+'BALANCE SHEET AUTOMOBILES'!F8 -> 17986 | G5: ='BALANCE SHEET AUTOMOBILES'!G7+'BALANCE SHEET AUTOMOBILES'!G8 -> 19807 | L5: Total Equity | M5: ='BALANCE SHEET IT'!C4+'BALANCE SHEET IT'!C5 -> 76351 | N5: ='BALANCE SHEET IT'!D4+'BALANCE SHEET IT'!D5 -> 75350 | O5: ='BALANCE SHEET IT'!E4+'BALANCE SHEET IT'!E5 -> 75407 | P5: ='BALANCE SHEET IT'!F4+'BALANCE SHEET IT'!F5 -> 88116 | Q5: ='BALANCE SHEET IT'!G4+'BALANCE SHEET IT'!G5 -> 95818
B6: Debt Equity Ratio | C6: =C5/C4 -> 101.32 | D6: =D5/D4 -> 93.946429 | E6: =E5/E4 -> 107.08333 | F6: =F5/F4 -> 130.33333 | G6: =G5/G4 -> 121.51534 | L6: Debt Equity Ratio | M6: =M5/M4 -> 14.338216 | N6: =N5/N4 -> 13.765071 | O6: =O5/O4 -> 9.0862755 | P6: =P5/P4 -> 10.541452 | Q6: =Q5/Q4 -> 11.646773
B8: EBIT | C8: ='P&L AUTOMOBILES'!C13-'P&L AUTOMOBILES'!C19 -> 3347 | D8: ='P&L AUTOMOBILES'!D13-'P&L AUTOMOBILES'!D19 -> 2729 | E8: ='P&L AUTOMOBILES'!E13-'P&L AUTOMOBILES'!E19 -> 3334 | F8: ='P&L AUTOMOBILES'!F13-'P&L AUTOMOBILES'!F19 -> 4550 | G8: ='P&L AUTOMOBILES'!G13-'P&L AUTOMOBILES'!G19 -> 5096 | L8: EBIT | M8: ='P&L IT'!C10-'P&L IT'!C15 -> 27694 | N8: ='P&L IT'!D10-'P&L IT'!D15 -> 31291 | O8: ='P&L IT'!E10-'P&L IT'!E15 -> 34846 | P8: ='P&L IT'!F10-'P&L IT'!F15 -> 35955 | Q8: ='P&L IT'!G10-'P&L IT'!G15 -> 38820
B9: Interest | C9: ='P&L AUTOMOBILES'!C18 -> 22 | D9: ='P&L AUTOMOBILES'!D18 -> 26 | E9: ='P&L AUTOMOBILES'!E18 -> 20 | F9: ='P&L AUTOMOBILES'!F18 -> 18 | G9: ='P&L AUTOMOBILES'!G18 -> 20 | L9: Interest | M9: ='P&L IT'!C15 -> 195 | N9: ='P&L IT'!D15 -> 200 | O9: ='P&L IT'!E15 -> 284 | P9: ='P&L IT'!F15 -> 470 | Q9: ='P&L IT'!G15 -> 416
B10: Interest Coverage Ratio | C10: =C9/C8 -> 0.0065730505 | D10: =D9/D8 -> 0.0095272994 | E10: =E9/E8 -> 0.0059988002 | F10: =F9/F8 -> 0.003956044 | G10: =G9/G8 -> 0.0039246468 | L10: Interest Coverage Ratio | M10: =M9/M8 -> 0.0070412364 | N10: =N9/N8 -> 0.0063916142 | O10: =O9/O8 -> 0.0081501464 | P10: =P9/P8 -> 0.013071895 | Q10: =Q9/Q8 -> 0.010716126
B12: Net Profit | C12: ='P&L AUTOMOBILES'!C22 -> 2964 | D12: ='P&L AUTOMOBILES'!D22 -> 2473 | E12: ='P&L AUTOMOBILES'!E22 -> 2911 | F12: ='P&L AUTOMOBILES'!F22 -> 3968 | G12: ='P&L AUTOMOBILES'!G22 -> 4610 | L12: Net Profit | M12: ='P&L IT'!C19 -> 19423 | N12: ='P&L IT'!D19 -> 22146 | O12: ='P&L IT'!E19 -> 24108 | P12: ='P&L IT'!F19 -> 26248 | Q12: ='P&L IT'!G19 -> 26750
B13: Total Assets | C13: ='BALANCE SHEET AUTOMOBILES'!C37 -> 22161 | D13: ='BALANCE SHEET AUTOMOBILES'!D37 -> 21714 | E13: ='BALANCE SHEET AUTOMOBILES'!E37 -> 23263 | F13: ='BALANCE SHEET AUTOMOBILES'!F37 -> 25572 | G13: ='BALANCE SHEET AUTOMOBILES'!G37 -> 27920 | L13: Total Assets | M13: ='BALANCE SHEET IT'!C33 -> 107511 | N13: ='BALANCE SHEET IT'!D33 -> 116729 | O13: ='BALANCE SHEET IT'!E33 -> 124596 | P13: ='BALANCE SHEET IT'!F33 -> 137360 | Q13: ='BALANCE SHEET IT'!G33 -> 147795
B14: Return on Assets | C14: =C13/C12 -> 7.4767206 | D14: =D13/D12 -> 8.7804286 | E14: =E13/E12 -> 7.9914119 | F14: =F13/F12 -> 6.4445565 | G14: =G13/G12 -> 6.0563991 | L14: Return on Assets | M14: =M13/M12 -> 5.5352417 | N14: =N13/N12 -> 5.2708841 | O14: =O13/O12 -> 5.1682429 | P14: =P13/P12 -> 5.2331606 | Q14: =Q13/Q12 -> 5.5250467
B16: Net Profit | C16: =C12 -> 2964 | D16: =D12 -> 2473 | E16: =E12 -> 2911 | F16: =F12 -> 3968 | G16: =G12 -> 4610 | L16: Net Profit | M16: =M12 -> 19423 | N16: =N12 -> 22146 | O16: =O12 -> 24108 | P16: =P12 -> 26248 | Q16: =Q12 -> 26750
B17: Share Holder Equity | C17: ='BALANCE SHEET AUTOMOBILES'!C8 -> 15158 | D17: ='BALANCE SHEET AUTOMOBILES'!D8 -> 15743 | E17: ='BALANCE SHEET AUTOMOBILES'!E8 -> 16665 | F17: ='BALANCE SHEET AUTOMOBILES'!F8 -> 17946 | G17: ='BALANCE SHEET AUTOMOBILES'!G8 -> 19767 | L17: Share Holder Equity | M17: ='BALANCE SHEET IT'!C5 -> 74227 | N17: ='BALANCE SHEET IT'!D5 -> 73252 | O17: ='BALANCE SHEET IT'!E5 -> 73338 | P17: ='BALANCE SHEET IT'!F5 -> 86045 | Q17: ='BALANCE SHEET IT'!G5 -> 93745
B18: Return on Equity | C18: =C17/C16 -> 5.1140351 | D18: =D17/D16 -> 6.3659523 | E18: =E17/E16 -> 5.7248368 | F18: =F17/F16 -> 4.5226815 | G18: =G17/G16 -> 4.2878525 | L18: Return on Equity | M18: =M17/M16 -> 3.8216033 | N18: =N17/N16 -> 3.3076854 | O18: =O17/O16 -> 3.0420607 | P18: =P17/P16 -> 3.2781545 | Q18: =Q17/Q16 -> 3.504486
C21: MARUTI SUZUKI | M21: TCS
B22: Particulars | C22: 2021 | D22: 2022 | E22: 2023 | F22: 2024 | G22: 2025 | L22: Particulars | M22: 2021 | N22: 2022 | O22: 2023 | P22: 2024 | Q22: 2025
B23: Total Debt | C23: ='BALANCE SHEET AUTOMOBILES'!K8 -> 531 | D23: ='BALANCE SHEET AUTOMOBILES'!L8 -> 419 | E23: ='BALANCE SHEET AUTOMOBILES'!M8 -> 1247 | F23: ='BALANCE SHEET AUTOMOBILES'!N8 -> 119 | G23: ='BALANCE SHEET AUTOMOBILES'!O8 -> 76 | L23: Total Debt | M23: ='BALANCE SHEET IT'!L6 -> 7795 | N23: ='BALANCE SHEET IT'!M6 -> 7818 | O23: ='BALANCE SHEET IT'!N6 -> 7688 | P23: ='BALANCE SHEET IT'!O6 -> 8021 | Q23: ='BALANCE SHEET IT'!P6 -> 9392
B24: Total Equity | C24: ='BALANCE SHEET AUTOMOBILES'!K6+'BALANCE SHEET AUTOMOBILES'!K7 -> 51367 | D24: ='BALANCE SHEET AUTOMOBILES'!L6+'BALANCE SHEET AUTOMOBILES'!L7 -> 54086 | E24: ='BALANCE SHEET AUTOMOBILES'!M6+'BALANCE SHEET AUTOMOBILES'!M7 -> 60382 | F24: ='BALANCE SHEET AUTOMOBILES'!N6+'BALANCE SHEET AUTOMOBILES'!N7 -> 83982 | G24: ='BALANCE SHEET AUTOMOBILES'!O6+'BALANCE SHEET AUTOMOBILES'!O7 -> 94047 | L24: Total Equity | M24: ='BALANCE SHEET IT'!L4+'BALANCE SHEET IT'!L5 -> 86433 | N24: ='BALANCE SHEET IT'!M4+'BALANCE SHEET IT'!M5 -> 89139 | O24: ='BALANCE SHEET IT'!N4+'BALANCE SHEET IT'!N5 -> 90424 | P24: ='BALANCE SHEET IT'!O4+'BALANCE SHEET IT'!O5 -> 90489 | Q24: ='BALANCE SHEET IT'!P4+'BALANCE SHEET IT'!P5 -> 94756
B25: Debt Equity Ratio | C25: =C24/C23 -> 96.736347 | D25: =D24/D23 -> 129.08353 | E25: =E24/E23 -> 48.421812 | F25: =F24/F23 -> 705.73109 | G25: =G24/G23 -> 1237.4605 | L25: Debt Equity Ratio | M25: =M24/M23 -> 11.088262 | N25: =N24/N23 -> 11.401765 | O25: =O24/O23 -> 11.761707 | P25: =P24/P23 -> 11.281511 | Q25: =Q24/Q23 -> 10.089012
B27: EBIT | C27: ='P&L AUTOMOBILES'!K15-'P&L AUTOMOBILES'!K21 -> 2372 | D27: ='P&L AUTOMOBILES'!L15-'P&L AUTOMOBILES'!L21 -> 2961 | E27: ='P&L AUTOMOBILES'!M15-'P&L AUTOMOBILES'!M21 -> 8196 | F27: ='P&L AUTOMOBILES'!N15-'P&L AUTOMOBILES'!N21 -> 13427 | G27: ='P&L AUTOMOBILES'!O15-'P&L AUTOMOBILES'!O21 -> 14667 | L27: EBIT | M27: ='P&L IT'!L11-'P&L IT'!L17 -> 42481 | N27: ='P&L IT'!M11-'P&L IT'!M17 -> 48453 | O27: ='P&L IT'!N11-'P&L IT'!N17 -> 54237 | P27: ='P&L IT'!O11-'P&L IT'!O17 -> 59311 | Q27: ='P&L IT'!P11-'P&L IT'!P17 -> 62165
B28: Interest | C28: ='P&L AUTOMOBILES'!K20 -> 101 | D28: ='P&L AUTOMOBILES'!L20 -> 126 | E28: ='P&L AUTOMOBILES'!M20 -> 187 | F28: ='P&L AUTOMOBILES'!N20 -> 193 | G28: ='P&L AUTOMOBILES'!O20 -> 193 | L28: Interest | M28: ='P&L IT'!L16 -> 637 | N28: ='P&L IT'!M16 -> 784 | O28: ='P&L IT'!N16 -> 779 | P28: ='P&L IT'!O16 -> 778 | Q28: ='P&L IT'!P16 -> 796
B29: Interest Coverage Ratio | C29: =C28/C27 -> 0.042580101 | D29: =D28/D27 -> 0.042553191 | E29: =E28/E27 -> 0.022816008 | F29: =F28/F27 -> 0.014374022 | G29: =G28/G27 -> 0.013158792 | L29: Interest Coverage Ratio | M29: =M28/M27 -> 0.014994939 | N29: =N28/N27 -> 0.016180629 | O29: =O28/O27 -> 0.014362889 | P29: =P28/P27 -> 0.013117297 | Q29: =Q28/Q27 -> 0.012804633
B31: Net Profit | C31: ='P&L AUTOMOBILES'!K24 -> 4230 | D31: ='P&L AUTOMOBILES'!L24 -> 3766 | E31: ='P&L AUTOMOBILES'!M24 -> 8049 | F31: ='P&L AUTOMOBILES'!N24 -> 13209 | G31: ='P&L AUTOMOBILES'!O24 -> 13955 | L31: Net Profit | M31: ='P&L IT'!L20 -> 32562 | N31: ='P&L IT'!M20 -> 38449 | O31: ='P&L IT'!N20 -> 42303 | P31: ='P&L IT'!O20 -> 46099 | Q31: ='P&L IT'!P20 -> 48797
B32: Total Assets | C32: ='BALANCE SHEET AUTOMOBILES'!K37 -> 70161 | D32: ='BALANCE SHEET AUTOMOBILES'!L37 -> 73394 | E32: ='BALANCE SHEET AUTOMOBILES'!M37 -> 83179 | F32: ='BALANCE SHEET AUTOMOBILES'!N37 -> 110285 | G32: ='BALANCE SHEET AUTOMOBILES'!O37 -> 125620 | L32: Total Assets | M32: ='BALANCE SHEET IT'!L37 -> 129992 | N32: ='BALANCE SHEET IT'!M37 -> 140924 | O32: ='BALANCE SHEET IT'!N37 -> 142859 | P32: ='BALANCE SHEET IT'!O37 -> 145472 | Q32: ='BALANCE SHEET IT'!P37 -> 158649
B33: Return on Assets | C33: =C32/C31 -> 16.586525 | D33: =D32/D31 -> 19.488582 | E33: =E32/E31 -> 10.334079 | F33: =F32/F31 -> 8.3492316 | G33: =G32/G31 -> 9.0017915 | L33: Return on Assets | M33: =M32/M31 -> 3.9921381 | N33: =N32/N31 -> 3.6652189 | O33: =O32/O31 -> 3.3770418 | P33: =P32/P31 -> 3.1556433 | Q33: =Q32/Q31 -> 3.251204
B35: Net Profit | C35: =C31 -> 4230 | D35: =D31 -> 3766 | E35: =E31 -> 8049 | F35: =F31 -> 13209 | G35: =G31 -> 13955 | L35: Net Profit | M35: =M31 -> 32562 | N35: =N31 -> 38449 | O35: =O31 -> 42303 | P35: =P31 -> 46099 | Q35: =Q31 -> 48797
B36: Share Holder Equity | C36: ='BALANCE SHEET AUTOMOBILES'!K7 -> 51216 | D36: ='BALANCE SHEET AUTOMOBILES'!L7 -> 53935 | E36: ='BALANCE SHEET AUTOMOBILES'!M7 -> 60231 | F36: ='BALANCE SHEET AUTOMOBILES'!N7 -> 83825 | G36: ='BALANCE SHEET AUTOMOBILES'!O7 -> 93890 | L36: Share Holder Equity | M36: ='BALANCE SHEET IT'!L5 -> 86063 | N36: ='BALANCE SHEET IT'!M5 -> 88773 | O36: ='BALANCE SHEET IT'!N5 -> 90058 | P36: ='BALANCE SHEET IT'!O5 -> 90127 | Q36: ='BALANCE SHEET IT'!P5 -> 94394
B37: Return on Equity | C37: =C36/C35 -> 12.107801 | D37: =D36/D35 -> 14.321561 | E37: =E36/E35 -> 7.4830414 | F37: =F36/F35 -> 6.3460519 | G37: =G36/G35 -> 6.7280545 | L37: Return on Equity | M37: =M36/M35 -> 2.6430502 | N37: =N36/N35 -> 2.3088507 | O37: =O36/O35 -> 2.1288797 | P37: =P36/P35 -> 1.9550749 | Q37: =Q36/Q35 -> 1.9344222
C40: Mahindra & Mahindra | M40: WIPRO
B41: Particulars | C41: 2021 | D41: 2022 | E41: 2023 | F41: 2024 | G41: 2025 | L41: Particulars | M41: 2021 | N41: 2022 | O41: 2023 | P41: 2024 | Q41: 2025
B42: Total Debt | C42: ='BALANCE SHEET AUTOMOBILES'!C49 -> 80625 | D42: ='BALANCE SHEET AUTOMOBILES'!D49 -> 77605 | E42: ='BALANCE SHEET AUTOMOBILES'!E49 -> 92247 | F42: ='BALANCE SHEET AUTOMOBILES'!F49 -> 108647 | G42: ='BALANCE SHEET AUTOMOBILES'!G49 -> 129025 | L42: Total Debt | M42: ='BALANCE SHEET IT'!C45 -> 10451 | N42: ='BALANCE SHEET IT'!D45 -> 17593 | O42: ='BALANCE SHEET IT'!E45 -> 17467 | P42: ='BALANCE SHEET IT'!F45 -> 16465 | Q42: ='BALANCE SHEET IT'!G45 -> 19204
B43: Total Equity | C43: ='BALANCE SHEET AUTOMOBILES'!C47+'BALANCE SHEET AUTOMOBILES'!C48 -> 41582 | D43: ='BALANCE SHEET AUTOMOBILES'!D47+'BALANCE SHEET AUTOMOBILES'!D48 -> 47123 | E43: ='BALANCE SHEET AUTOMOBILES'!E47+'BALANCE SHEET AUTOMOBILES'!E48 -> 56366 | F43: ='BALANCE SHEET AUTOMOBILES'!F47+'BALANCE SHEET AUTOMOBILES'!F48 -> 66190 | G43: ='BALANCE SHEET AUTOMOBILES'!G47+'BALANCE SHEET AUTOMOBILES'!G48 -> 77039 | L43: Total Equity | M43: ='BALANCE SHEET IT'!C43+'BALANCE SHEET IT'!C44 -> 54901 | N43: ='BALANCE SHEET IT'!D43+'BALANCE SHEET IT'!D44 -> 65403 | O43: ='BALANCE SHEET IT'!E43+'BALANCE SHEET IT'!E44 -> 77668 | P43: ='BALANCE SHEET IT'!F43+'BALANCE SHEET IT'!F44 -> 74988 | Q43: ='BALANCE SHEET IT'!G43+'BALANCE SHEET IT'!G44 -> 82830
B44: Debt Equity Ratio | C44: =C43/C42 -> 0.51574574 | D44: =D43/D42 -> 0.60721603 | E44: =E43/E42 -> 0.61103342 | F44: =F43/F42 -> 0.60922069 | G44: =G43/G42 -> 0.59708584 | L44: Debt Equity Ratio | M44: =M43/M42 -> 5.2531815 | N44: =N43/N42 -> 3.7175581 | O44: =O43/O42 -> 4.4465564 | P44: =P43/P42 -> 4.5543881 | Q44: =Q43/Q42 -> 4.3131639
B46: EBIT | C46: ='P&L AUTOMOBILES'!C48-'P&L AUTOMOBILES'!C54 -> 8109 | D46: ='P&L AUTOMOBILES'!D48-'P&L AUTOMOBILES'!D54 -> 11175 | E46: ='P&L AUTOMOBILES'!E48-'P&L AUTOMOBILES'!E54 -> 15928 | F46: ='P&L AUTOMOBILES'!F48-'P&L AUTOMOBILES'!F54 -> 20168 | G46: ='P&L AUTOMOBILES'!G48-'P&L AUTOMOBILES'!G54 -> 24444 | L46: EBIT | M46: ='P&L IT'!C41-'P&L IT'!C46 -> 14262 | N46: ='P&L IT'!D41-'P&L IT'!D46 -> 16152 | O46: ='P&L IT'!E41-'P&L IT'!E46 -> 15831 | P46: ='P&L IT'!F41-'P&L IT'!F46 -> 15497 | Q46: ='P&L IT'!G41-'P&L IT'!G46 -> 16544
B47: Interest | C47: ='P&L AUTOMOBILES'!C53 -> 6102 | D47: ='P&L AUTOMOBILES'!D53 -> 5018 | E47: ='P&L AUTOMOBILES'!E53 -> 5830 | F47: ='P&L AUTOMOBILES'!F53 -> 7488 | G47: ='P&L AUTOMOBILES'!G53 -> 9083 | L47: Interest | M47: ='P&L IT'!C46 -> 509 | N47: ='P&L IT'!D46 -> 532 | O47: ='P&L IT'!E46 -> 1008 | P47: ='P&L IT'!F46 -> 1255 | Q47: ='P&L IT'!G46 -> 1477
B48: Interest Coverage Ratio | C48: =C47/C46 -> 0.75249723 | D48: =D47/D46 -> 0.44903803 | E48: =E47/E46 -> 0.3660221 | F48: =F47/F46 -> 0.37128124 | G48: =G47/G46 -> 0.37158403 | L48: Interest Coverage Ratio | M48: =M47/M46 -> 0.035689244 | N48: =N47/N46 -> 0.032937098 | O48: =O47/O46 -> 0.063672541 | P48: =P47/P46 -> 0.080983416 | Q48: =Q47/Q46 -> 0.089277079
B50: Net Profit | C50: ='P&L AUTOMOBILES'!C57 -> 1512 | D50: ='P&L AUTOMOBILES'!D57 -> 7253 | E50: ='P&L AUTOMOBILES'!E57 -> 11374 | F50: ='P&L AUTOMOBILES'!F57 -> 12270 | G50: ='P&L AUTOMOBILES'!G57 -> 14073 | L50: Net Profit | M50: ='P&L IT'!C50 -> 10868 | N50: ='P&L IT'!D50 -> 12243 | O50: ='P&L IT'!E50 -> 11366 | P50: ='P&L IT'!F50 -> 11112 | Q50: ='P&L IT'!G50 -> 13218
B51: Total Assets | C51: ='BALANCE SHEET AUTOMOBILES'!C83 -> 164968 | D51: ='BALANCE SHEET AUTOMOBILES'!D83 -> 172388 | E51: ='BALANCE SHEET AUTOMOBILES'!E83 -> 204283 | F51: ='BALANCE SHEET AUTOMOBILES'!F83 -> 234722 | G51: ='BALANCE SHEET AUTOMOBILES'!G83 -> 276013 | L51: Total Assets | M51: ='BALANCE SHEET IT'!C76 -> 82566 | N51: ='BALANCE SHEET IT'!D76 -> 107276 | O51: ='BALANCE SHEET IT'!E76 -> 116924 | P51: ='BALANCE SHEET IT'!F76 -> 115064 | Q51: ='BALANCE SHEET IT'!G76 -> 128396
B52: Return on Assets | C52: =C51/C50 -> 109.10582 | D52: =D51/D50 -> 23.76782 | E52: =E51/E50 -> 17.960524 | F52: =F51/F50 -> 19.129747 | G52: =G51/G50 -> 19.612947 | L52: Return on Assets | M52: =M51/M50 -> 7.597166 | N52: =N51/N50 -> 8.7622315 | O52: =O51/O50 -> 10.287172 | P52: =P51/P50 -> 10.354932 | Q52: =Q51/Q50 -> 9.7137237
B54: Net Profit | C54: =C50 -> 1512 | D54: =D50 -> 7253 | E54: =E50 -> 11374 | F54: =F50 -> 12270 | G54: =G50 -> 14073 | L54: Net Profit | M54: =M50 -> 10868 | N54: =N50 -> 12243 | O54: =O50 -> 11366 | P54: =P50 -> 11112 | Q54: =Q50 -> 13218
...

Sheet DASHBOARD

Sheet LEVERAGE ANALYSIS
A1: Leverage Summary for All Companies
A3: 1. Maruti Suzuki | J3: 1. Wipro
A5: Debt-Equity Ratio: ~0.00 Classification: Under-leveraged Summary: Maruti is almost debt-free and relies overwhelmingly on equity financing. It carries extremely low financial risk. | J5: Debt-Equity Ratio: ~0.20 Classification: Under-leveraged Summary: WIPRO operates with low debt levels, indicating conservative financing and low financial leverage.
A11: 2. TVS Motors | J11: 2. HCL Technologies
A13: Debt-Equity Ratio: Between 0.24 and 0.31 Classification: Under-leveraged Summary: Ratio below 1 indicates the company is not heavily reliant on debt. Debt are moderate and well below equity. Financial risk is low. | J13: Debt-Equity Ratio: ~0.03 Classification: Under-leveraged Summary: HCL uses very little debt. Its operations are primarily supported by equity, resulting in low leverage risk.
A19: 3. Mahindra & Mahindra (M&M) | J19: 3. TCS (Tata Consultancy Services)
A21: Debt-Equity Ratio: ~1.63 Classification: Over-leveraged Summary: M&M uses considerable debt in its capital structure. A D/E above 1 shows higher reliance on borrowed funds compared to equity. | J21: Debt-Equity Ratio: ~0.10 Classification: Under-leveraged Summary: TCS maintains a very low D/E ratio, typical for major IT companies. The firm is highly stable with minimal dependence on debt.
A28: 4. Hero Motors | J28: 4. Infosys
A30: Debt–Equity Ratio: ~1.20 Classification: Over-leveraged Summary: Hero Motors relies heavily on debt financing, indicating high financial leverage and greater exposure to interest and earnings volatility. | J30: Debt–Equity Ratio: ~0.10 Classification: Under-leveraged Summary: Infosys operates with very low debt and strong equity support, showing conservative financing, low financial risk, and stable long-term performance.
